Workbook

Sheet Video Ideas
A1: ID | B1: Theme | C1: Sub-theme | D1: Video Idea | E1: Description / Format | F1: Relevance (1-5) | G1: Virality (1-5) | H1: Priority Score (/10) | I1: Complexity (1-5) | J1: Est. Production Time | K1: Face Cam | L1: Status | M1: Post Date | N1: Time | O1: Hook (opening line) | P1: Caption (post description) | Q1: Music / Audio
A2: 1 | B2: Brand & Promo | C2: App launch | D2: Hero promo video | E2: Explain Swappanini on camera: track every sticker, find doubles, complete your album with collectors worldwide | F2: 5 | G2: 2 | H2: =F2+G2 -> 7 | I2: 3 | J2: 30-45 min | K2: Yes | L2: Idea | M2: 16/07 | N2: 9h | O2: You collect Panini World Cup 2026? This is the app you need 👀 | P2: Track every sticker. Find your doubles. Complete your album — with collectors around the world 🌍 Smart matching. Free. No credit card. No money exchanged. → swappanini.com #Swappanini #Panini2026 #WorldCup2026 #PaniniAlbum #StickerSwap | Q2: Build-up / reveal trending sound (suspense drop)
A3: 2 | B3: Brand & Promo | C3: Community concept | D3: "Collective album" video | E3: Show the community swap experience — multiple albums completing each other visually | F3: 5 | G3: 3 | H3: =F3+G3 -> 8 | I3: 3 | J3: 30-45 min | K3: Optional | L3: Idea | M3: 29/06 | N3: 18h
A4: 3 | B4: Collection Journey | C4: Best lineup | D4: My current best XI | E4: Best starting XI built only from stickers currently owned — update as collection grows | F4: 5 | G4: 4 | H4: =F4+G4 -> 9 | I4: 1 | J4: 10-15 min | K4: Yes | L4: Idea | M4: 20/06 | N4: 21h
A5: 4 | B5: Collection Journey | C5: Tips & tricks | D5: Coca-Cola pack-opening trick | E5: Lifehack to 'control' which sticker comes out using a bottle — viral format | F5: 3 | G5: 5 | H5: =F5+G5 -> 8 | I5: 1 | J5: <1 min | K5: No | L5: Idea | M5: 25/06 | N5: 13h
A6: 5 | B6: Collection Journey | C6: Tips & tricks | D6: Sticker placement tutorial + my fails | E6: How to glue stickers properly + humorous segment of your own badly-placed ones | F6: 3 | G6: 4 | H6: =F6+G6 -> 7 | I6: 2 | J6: 10-15 min | K6: Optional | L6: Idea | M6: 23/06 | N6: 18h
A7: 6 | B7: Collection Journey | C7: Collection showcase | D7: All my crests/badges | E7: Showcase of the full crest/badge page of the album | F7: 4 | G7: 2 | H7: =F7+G7 -> 6 | I7: 1 | J7: 10-15 min | K7: Optional | L7: Idea | M7: 25/06 | N7: 9h
A8: 7 | B8: Collection Journey | C8: Comedy/Showcase | D8: "Payday = packs" haul | E8: Already filmed — reframed as 'when you get paid and spend it all on packs' comedy format | F8: 3 | G8: 5 | H8: =F8+G8 -> 8 | I8: 1 | J8: Ready (0 min) | K8: Yes | L8: Ready to post | M8: 18/06 | N8: 21h
A9: 8 | B9: Collection Journey | C9: Progress milestones | D9: Album completion: 50% | E9: Short milestone update — album 50% complete. Already at this level — post ASAP | F9: 5 | G9: 4 | H9: =F9+G9 -> 9 | I9: 1 | J9: <1 min | K9: Yes | L9: Idea | M9: 17/06 | N9: 13h | O9: My Panini album is already 50% complete 👀 halfway there! | P9: 50% done — and I still need YOUR doubles to finish it 🔄 Track your own progress + find swap matches at swappanini.com ⬆️ #PaniniAlbum #WorldCup2026 #Panini2026 #AlbumCompletion #Swappanini | Q9: Upbeat achievement sound / trending 'level up' audio
A10: 9 | B10: Collection Journey | C10: Progress milestones | D10: Album completion: 65% | E10: Short milestone update — album 65% complete | F10: 5 | G10: 4 | H10: =F10+G10 -> 9 | I10: 1 | J10: <1 min | K10: Yes | L10: Idea | M10: 27/06 | N10: 9h
A11: 10 | B11: Collection Journey | C11: Progress milestones | D11: Album completion: 75% | E11: Short milestone update — album 75% complete | F11: 5 | G11: 4 | H11: =F11+G11 -> 9 | I11: 1 | J11: <1 min | K11: Yes | L11: Idea | M11: 04/07 | N11: 9h
A12: 11 | B12: Collection Journey | C12: Progress milestones | D12: Album completion: 80% | E12: Short milestone update — album 80% complete | F12: 5 | G12: 4 | H12: =F12+G12 -> 9 | I12: 1 | J12: <1 min | K12: Yes | L12: Idea | M12: 07/07 | N12: 9h
A13: 12 | B13: Collection Journey | C13: Progress milestones | D13: Album completion: 85% | E13: Short milestone update — album 85% complete | F13: 5 | G13: 4 | H13: =F13+G13 -> 9 | I13: 1 | J13: <1 min | K13: Yes | L13: Idea | M13: 11/07 | N13: 9h
A14: 13 | B14: Collection Journey | C14: Progress milestones | D14: Album completion: 90% | E14: Short milestone update — album 90% complete | F14: 5 | G14: 4 | H14: =F14+G14 -> 9 | I14: 1 | J14: <1 min | K14: Yes | L14: Idea | M14: 13/07 | N14: 9h
A15: 14 | B15: Collection Journey | C15: Progress milestones | D15: Album completion: 95% | E15: Short milestone update — album 95% complete | F15: 5 | G15: 4 | H15: =F15+G15 -> 9 | I15: 1 | J15: <1 min | K15: Yes | L15: Idea | M15: 14/07 | N15: 18h
A16: 15 | B16: Collection Journey | C16: Progress milestones | D16: Album completion: 100% (celebration) | E16: The big reveal — album finally complete, celebration format | F16: 5 | G16: 5 | H16: =F16+G16 -> 10 | I16: 2 | J16: 15-20 min | K16: Yes | L16: Idea | M16: 19/07 | N16: 21h
A17: 16 | B17: Collection Journey | C17: Visual effects | D17: Slow-motion: player walks to his slot | E17: Slow-mo / visual effect where a 'player' physically travels to his sticker slot in the album | F17: 4 | G17: 4 | H17: =F17+G17 -> 8 | I17: 3 | J17: 30-45 min | K17: Yes | L17: Idea | M17: 24/06 | N17: 13h
A18: 17 | B18: Collection Journey | C18: Player content (chants) | D18: Chant video: Mohamed Salah | E18: Sticker reveal for Salah (Egypt/Liverpool) set to the iconic 'Mo Salah' terrace chant — post before Egypt vs NZ (Jun 22 3am Paris) | F18: 3 | G18: 5 | H18: =F18+G18 -> 8 | I18: 1 | J18: 10-15 min | K18: Optional | L18: Idea | M18: 21/06 | N18: 19h | O18: The Salah sticker — with THE chant that goes with it 🎵 | P18: Mo Salah, Mo Salah, running down the wing 🎶 Egypt play New Zealand tomorrow — who has Salah as a double? Swap at swappanini.com 🌍 #MoSalah #Egypt #WorldCup2026 #PaniniChant #Swappanini | Q18: Mo Salah — The Egyptian King (original Liverpool terrace chant)
A19: 18 | B19: Collection Journey | C19: Player content (chants) | D19: Chant video: Erling Haaland | E19: Sticker reveal for Haaland (Norway/Man City) set to his cult terrace chant — post before Norway vs France (Jun 26 21h) | F19: 3 | G19: 5 | H19: =F19+G19 -> 8 | I19: 1 | J19: 10-15 min | K19: Optional | L19: Idea | M19: 25/06 | N19: 18h
A20: 19 | B20: Collection Journey | C20: Player content (chants) | D20: Chant video: Martin Odegaard | E20: Sticker reveal for Odegaard (Norway/Arsenal) set to the 'Ode-gaard' chant — post before Norway vs Senegal (Jun 23 2am Paris) | F20: 3 | G20: 4 | H20: =F20+G20 -> 7 | I20: 1 | J20: 10-15 min | K20: Optional | L20: Idea | M20: 22/06 | N20: 13h
A21: 20 | B21: Collection Journey | C21: Player content (chants) | D21: Chant video: John McGinn | E21: Sticker reveal for McGinn (Scotland/Aston Villa) — cult-favourite chant — post Jun 19 9h (Scotland-Morocco day) | F21: 3 | G21: 5 | H21: =F21+G21 -> 8 | I21: 1 | J21: 10-15 min | K21: Optional | L21: Idea | M21: 10/07 | N21: 18h | O21: The McGinn sticker — with the chant that goes with it 🎵🏴󠁧󠁢󠁳󠁣󠁴󠁿 | P21: Come on John McGinn! Scotland vs Morocco tonight 🏴󠁧󠁢󠁳󠁣󠁴󠁿🇲🇦 Who has McGinn as a double? Swap at swappanini.com #JohnMcGinn #Scotland #WorldCup2026 #PaniniChant #Swappanini | Q21: John McGinn chant — original Scotland terrace audio
A22: 21 | B22: Collection Journey | C22: Player content (chants) | D22: Chant video: Virgil van Dijk | E22: Sticker reveal for Van Dijk (Netherlands/Liverpool) — the captain's chant | F22: 3 | G22: 4 | H22: =F22+G22 -> 7 | I22: 1 | J22: 10-15 min | K22: Optional | L22: Idea | M22: 26/06 | N22: 13h
A23: 22 | B23: Collection Journey | C23: Player content (chants) | D23: Chant video: Granit Xhaka | E23: Sticker reveal for Xhaka (Switzerland) — the iconic 'Xhaka, woah' chant | F23: 3 | G23: 5 | H23: =F23+G23 -> 8 | I23: 1 | J23: 10-15 min | K23: Optional | L23: Idea | M23: 02/07 | N23: 9h
A24: 23 | B24: Collection Journey | C24: Player content (chants) | D24: Chant video: Andrew Robertson | E24: Sticker reveal for Robertson (Scotland/Liverpool) — post Jun 19 13h (pre Scotland-Morocco) or Jun 24 18h (pre Scotland-Brazil) | F24: 3 | G24: 4 | H24: =F24+G24 -> 7 | I24: 1 | J24: 10-15 min | K24: Optional | L24: Idea | M24: 24/06 | N24: 18h | O24: Robertson sticker — with the chant 🎵🏴󠁧󠁢󠁳󠁣󠁴󠁿 | P24: Andrew Robertson — Scotland's captain tonight vs Morocco 🏴󠁧󠁢󠁳󠁣󠁴󠁿 Swap your doubles at swappanini.com 🌍 #Robertson #Scotland #WorldCup2026 #PaniniChant #Swappanini | Q24: Robertson fan chant — original Scotland terrace audio
A25: 24 | B25: Country Series (Complete Squad) | C25: Team set | D25: Complete squad: Brazil | E25: Lay out every Brazil sticker — post Jun 20 (day after Brazil-Haiti) or Jun 24 pre Scotland-Brazil | F25: 4 | G25: 5 | H25: =F25+G25 -> 9 | I25: 1 | J25: 10-15 min | K25: Optional | L25: Idea | M25: 20/06 | N25: 9h
A26: 25 | B26: Country Series (Complete Squad) | C26: Team set | D26: Complete squad: France | E26: Lay out every France sticker — post on a France match day (Jun 22 or Jun 26) | F26: 4 | G26: 5 | H26: =F26+G26 -> 9 | I26: 1 | J26: 10-15 min | K26: Optional | L26: Idea | M26: 26/06 | N26: 18h
A27: 26 | B27: Country Series (Complete Squad) | C27: Team set | D27: Complete squad: England | E27: Lay out every England sticker — post Jun 17 pre England-Croatia | F27: 4 | G27: 4 | H27: =F27+G27 -> 8 | I27: 1 | J27: 10-15 min | K27: Optional | L27: Idea | M27: 27/06 | N27: 18h | O27: 🏴󠁧󠁢󠁥󠁮󠁧󠁿 England tonight — here's my full England squad in the album | P27: England vs Croatia — every Three Lions sticker laid out 🏴󠁧󠁢󠁥󠁮󠁧󠁿 Missing any? Swap at swappanini.com 🌍 #EnglandVsCroatia #ThreeLions #WorldCup2026 #Panini #Swappanini | Q27: Three Lions (It's Coming Home) — ≤15s clip
A28: 27 | B28: Country Series (Complete Squad) | C28: Team set | D28: Complete squad: Spain | E28: Lay out every Spain sticker | F28: 4 | G28: 4 | H28: =F28+G28 -> 8 | I28: 1 | J28: 10-15 min | K28: Optional | L28: Idea | M28: 07/07 | N28: 18h
A29: 28 | B29: Country Series (Complete Squad) | C29: Team set | D29: Complete squad: Uruguay | E29: Lay out every Uruguay sticker | F29: 4 | G29: 3 | H29: =F29+G29 -> 7 | I29: 1 | J29: 10-15 min | K29: Optional | L29: Idea | M29: 29/06 | N29: 9h
A30: 29 | B30: Country Series (Complete Squad) | C30: Team set | D30: Complete squad: Colombia | E30: Lay out every Colombia sticker | F30: 4 | G30: 3 | H30: =F30+G30 -> 7 | I30: 1 | J30: 10-15 min | K30: Optional | L30: Idea | M30: 17/07 | N30: 18h
A31: 30 | B31: Country Series (Complete Squad) | C31: Team set | D31: Complete squad: Scotland | E31: Lay out every Scotland sticker — post Jun 19 18h pre Scotland-Morocco | F31: 4 | G31: 3 | H31: =F31+G31 -> 7 | I31: 1 | J31: 10-15 min | K31: Optional | L31: Idea | M31: 19/06 | N31: 18h | O31: 🏴󠁧󠁢󠁳󠁣󠁴󠁿 Scotland vs Morocco tonight — here's my full Scotland squad in the album | P31: Come on Scotland! 🔵⚪ Every sticker laid out — who's still missing from yours? Swap doubles at swappanini.com 🌍 #ScotlandVsMorocco #WorldCup2026 #Panini #Scotland #Swappanini | Q31: Flower of Scotland — short clip ≤15s
A32: 31 | B32: Country Series (Complete Squad) | C32: Team set | D32: Complete squad: Ecuador | E32: Lay out every Ecuador sticker — ties into 'send him Ecuador' joke | F32: 4 | G32: 3 | H32: =F32+G32 -> 7 | I32: 1 | J32: 10-15 min | K32: Optional | L32: Idea | M32: 05/07 | N32: 9h
A33: 32 | B33: Country Series (Complete Squad) | C33: Team set | D33: Complete squad: Panama | E33: Lay out every Panama sticker — novelty: first-ever World Cup squad | F33: 4 | G33: 2 | H33: =F33+G33 -> 6 | I33: 1 | J33: 10-15 min | K33: Optional | L33: Idea | M33: 11/07 | N33: 18h
A34: 33 | B34: Country Series (Complete Squad) | C34: Team set | D34: Complete squad: Bosnia | E34: Lay out every Bosnia sticker | F34: 4 | G34: 2 | H34: =F34+G34 -> 6 | I34: 1 | J34: 10-15 min | K34: Optional | L34: Idea | M34: 09/07 | N34: 18h
A35: 34 | B35: Country Series (Complete Squad) | C35: Team set | D35: Complete squad: DR Congo | E35: Lay out every DR Congo sticker — historic qualification story | F35: 4 | G35: 2 | H35: =F35+G35 -> 6 | I35: 1 | J35: 10-15 min | K35: Optional | L35: Idea | M35: 03/07 | N35: 9h
A36: 35 | B36: Humor & Sketches | C36: Delivery parody | D36: Sticker pack "Uber Eats" delivery | E36: Sketch: pack delivered like a food order, with a delivery driver cameo | F36: 3 | G36: 5 | H36: =F36+G36 -> 8 | I36: 3 | J36: 30-45 min | K36: Yes | L36: Idea | M36: 15/07 | N36: 9h
A37: 36 | B37: Humor & Sketches | C37: Delivery parody | D37: Eurostar pack delivery | E37: Same delivery gag set on/around the Eurostar — international swap angle | F37: 4 | G37: 4 | H37: =F37+G37 -> 8 | I37: 4 | J37: 45-60 min | K37: Yes | L37: Idea | M37: 09/07 | N37: 9h
A38: 37 | B38: Humor & Sketches | C38: Couple sketch | D38: "Wrong bag" shopping swap | E38: Already filmed — partner hands you a garment; you open it and it's a sticker pack | F38: 2 | G38: 5 | H38: =F38+G38 -> 7 | I38: 1 | J38: Ready (0 min) | K38: Yes | L38: Ready to post | M38: 20/06 | N38: 18h
A39: 38 | B39: Humor & Sketches | C39: Trend audio | D39: "I don't cook, I don't clean" (...I collect stickers) | E39: Adapt the trending audio to the sticker collector persona | F39: 3 | G39: 5 | H39: =F39+G39 -> 8 | I39: 1 | J39: <1 min | K39: Yes | L39: Idea | M39: 01/07 | N39: 9h
A40: 39 | B40: Humor & Sketches | C40: Couple sketch | D40: "Please send him Ecuador!" | E40: Couple at Ecuador reference; punchline — she begs for the missing Ecuador sticker | F40: 4 | G40: 5 | H40: =F40+G40 -> 9 | I40: 3 | J40: 30-45 min | K40: Yes | L40: Idea | M40: 14/07 | N40: 9h
...

Sheet Executive Summary
A1: Swappanini — Content Dashboard
A3: Key Stats
A4: Total ideas logged | B4: =COUNTA('Video Ideas'!A2:A68) -> 67
A5: Average Priority (/10) | B5: =ROUND(AVERAGE('Video Ideas'!H2:H68),1) -> 8
A6: Ready to post NOW | B6: =COUNTIF('Video Ideas'!J2:J68,"Ready (0 min)") -> 6
A7: Posts scheduled (date set) | B7: =COUNTA('Video Ideas'!M2:M68) -> 67
A8: Quick wins (Priority≥9, Complexity=1) | B8: =COUNTIFS('Video Ideas'!H2:H68,">=9",'Video Ideas'!I2:I68,1) -> 13
A10: Breakdown by Theme
A11: Theme | B11: # Ideas | C11: Avg Priority | D11: Avg Complexity
A12: Brand & Promo | B12: =COUNTIF('Video Ideas'!B2:B68,A12) -> 2 | C12: =ROUND(AVERAGEIF('Video Ideas'!B2:B68,A12,'Video Ideas'!H2:H68),1) -> 7.5 | D12: =ROUND(AVERAGEIF('Video Ideas'!B2:B68,A12,'Video Ideas'!I2:I68),1) -> 3
A13: Collection Journey | B13: =COUNTIF('Video Ideas'!B2:B68,A13) -> 21 | C13: =ROUND(AVERAGEIF('Video Ideas'!B2:B68,A13,'Video Ideas'!H2:H68),1) -> 8.2 | D13: =ROUND(AVERAGEIF('Video Ideas'!B2:B68,A13,'Video Ideas'!I2:I68),1) -> 1.2
A14: Country Series (Complete Squad) | B14: =COUNTIF('Video Ideas'!B2:B68,A14) -> 11 | C14: =ROUND(AVERAGEIF('Video Ideas'!B2:B68,A14,'Video Ideas'!H2:H68),1) -> 7.3 | D14: =ROUND(AVERAGEIF('Video Ideas'!B2:B68,A14,'Video Ideas'!I2:I68),1) -> 1
A15: Humor & Sketches | B15: =COUNTIF('Video Ideas'!B2:B68,A15) -> 8 | C15: =ROUND(AVERAGEIF('Video Ideas'!B2:B68,A15,'Video Ideas'!H2:H68),1) -> 7.5 | D15: =ROUND(AVERAGEIF('Video Ideas'!B2:B68,A15,'Video Ideas'!I2:I68),1) -> 2.9
A16: Community & Growth Loops | B16: =COUNTIF('Video Ideas'!B2:B68,A16) -> 6 | C16: =ROUND(AVERAGEIF('Video Ideas'!B2:B68,A16,'Video Ideas'!H2:H68),1) -> 9.5 | D16: =ROUND(AVERAGEIF('Video Ideas'!B2:B68,A16,'Video Ideas'!I2:I68),1) -> 3
A17: Doubles & Swap Demo | B17: =COUNTIF('Video Ideas'!B2:B68,A17) -> 5 | C17: =ROUND(AVERAGEIF('Video Ideas'!B2:B68,A17,'Video Ideas'!H2:H68),1) -> 8.6 | D17: =ROUND(AVERAGEIF('Video Ideas'!B2:B68,A17,'Video Ideas'!I2:I68),1) -> 1.2
A18: Pack Opening Series | B18: =COUNTIF('Video Ideas'!B2:B68,A18) -> 14 | C18: =ROUND(AVERAGEIF('Video Ideas'!B2:B68,A18,'Video Ideas'!H2:H68),1) -> 7.6 | D18: =ROUND(AVERAGEIF('Video Ideas'!B2:B68,A18,'Video Ideas'!I2:I68),1) -> 1.6
A20: Quick Wins — Post First (Priority ≥9, Complexity =1)
A21: Video Idea | B21: Theme | C21: Priority | D21: Complexity | E21: Face Cam | F21: Post Date
A22: ='Video Ideas'!D4 -> My current best XI | B22: ='Video Ideas'!B4 -> Collection Journey | C22: ='Video Ideas'!H4 -> 9 | D22: ='Video Ideas'!I4 -> 1 | E22: ='Video Ideas'!K4 -> Yes | F22: ='Video Ideas'!M4 -> 20/06
A23: ='Video Ideas'!D9 -> Album completion: 50% | B23: ='Video Ideas'!B9 -> Collection Journey | C23: ='Video Ideas'!H9 -> 9 | D23: ='Video Ideas'!I9 -> 1 | E23: ='Video Ideas'!K9 -> Yes | F23: ='Video Ideas'!M9 -> 17/06
A24: ='Video Ideas'!D10 -> Album completion: 65% | B24: ='Video Ideas'!B10 -> Collection Journey | C24: ='Video Ideas'!H10 -> 9 | D24: ='Video Ideas'!I10 -> 1 | E24: ='Video Ideas'!K10 -> Yes | F24: ='Video Ideas'!M10 -> 27/06
A25: ='Video Ideas'!D11 -> Album completion: 75% | B25: ='Video Ideas'!B11 -> Collection Journey | C25: ='Video Ideas'!H11 -> 9 | D25: ='Video Ideas'!I11 -> 1 | E25: ='Video Ideas'!K11 -> Yes | F25: ='Video Ideas'!M11 -> 04/07
A26: ='Video Ideas'!D12 -> Album completion: 80% | B26: ='Video Ideas'!B12 -> Collection Journey | C26: ='Video Ideas'!H12 -> 9 | D26: ='Video Ideas'!I12 -> 1 | E26: ='Video Ideas'!K12 -> Yes | F26: ='Video Ideas'!M12 -> 07/07
A27: ='Video Ideas'!D13 -> Album completion: 85% | B27: ='Video Ideas'!B13 -> Collection Journey | C27: ='Video Ideas'!H13 -> 9 | D27: ='Video Ideas'!I13 -> 1 | E27: ='Video Ideas'!K13 -> Yes | F27: ='Video Ideas'!M13 -> 11/07
A28: ='Video Ideas'!D14 -> Album completion: 90% | B28: ='Video Ideas'!B14 -> Collection Journey | C28: ='Video Ideas'!H14 -> 9 | D28: ='Video Ideas'!I14 -> 1 | E28: ='Video Ideas'!K14 -> Yes | F28: ='Video Ideas'!M14 -> 13/07
A29: ='Video Ideas'!D15 -> Album completion: 95% | B29: ='Video Ideas'!B15 -> Collection Journey | C29: ='Video Ideas'!H15 -> 9 | D29: ='Video Ideas'!I15 -> 1 | E29: ='Video Ideas'!K15 -> Yes | F29: ='Video Ideas'!M15 -> 14/07
A30: ='Video Ideas'!D25 -> Complete squad: Brazil | B30: ='Video Ideas'!B25 -> Country Series (Complete Squad) | C30: ='Video Ideas'!H25 -> 9 | D30: ='Video Ideas'!I25 -> 1 | E30: ='Video Ideas'!K25 -> Optional | F30: ='Video Ideas'!M25 -> 20/06
A31: ='Video Ideas'!D26 -> Complete squad: France | B31: ='Video Ideas'!B26 -> Country Series (Complete Squad) | C31: ='Video Ideas'!H26 -> 9 | D31: ='Video Ideas'!I26 -> 1 | E31: ='Video Ideas'!K26 -> Optional | F31: ='Video Ideas'!M26 -> 26/06
A32: ='Video Ideas'!D51 -> "Exchange alert" live matching | B32: ='Video Ideas'!B51 -> Doubles & Swap Demo | C32: ='Video Ideas'!H51 -> 9 | D32: ='Video Ideas'!I51 -> 1 | E32: ='Video Ideas'!K51 -> Yes | F32: ='Video Ideas'!M51 -> 20/06
A33: ='Video Ideas'!D54 -> Quick swap demo — filmed on the spot | B33: ='Video Ideas'!B54 -> Doubles & Swap Demo | C33: ='Video Ideas'!H54 -> 10 | D33: ='Video Ideas'!I54 -> 1 | E33: ='Video Ideas'!K54 -> Yes | F33: ='Video Ideas'!M54 -> 17/06
A34: ='Video Ideas'!D57 -> Pack Opening #11 — Messi themed | B34: ='Video Ideas'!B57 -> Pack Opening Series | C34: ='Video Ideas'!H57 -> 9 | D34: ='Video Ideas'!I57 -> 1 | E34: ='Video Ideas'!K57 -> Yes | F34: ='Video Ideas'!M57 -> 18/06
